Workbook

Sheet Lisez-moi
A1: Classeur de calculs obligataires sur la courbe zéro-coupon de la Banque du Canada.
A2: Courbe du 2026-08-12 (source : bankofcanada.ca, décimales converties en %).
A3: Convention : composition continue, facteur d'actualisation EXP(-z*t) (BIS Papers 25).
A4: Feuille Obligation : changez le coupon (B2) ou l'échéance (B3), tout se recalcule.
A5: L'échéance est arrondie au pas de coupon le plus proche (0,5 an par défaut) et plafonne à 30 ans.
A6: Feuille Chocs : les six scénarios IRRBB (CAD : 200/275/175 pb, BCBS d578 2024) revalorisent l'obligation.
A7: Les formules sont vivantes : aucun chiffre collé, tout part de la feuille Courbe.

Sheet Courbe
A1: Échéance (années) | B1: Taux zéro (%)
A2: 0.25 | B2: 2.2948
A3: 0.5 | B3: 2.4131
A4: 0.75 | B4: 2.5326
A5: 1 | B5: 2.6516
A6: 1.25 | B6: 2.7697
A7: 1.5 | B7: 2.839
A8: 1.75 | B8: 2.8987
A9: 2 | B9: 2.9506
A10: 2.25 | B10: 2.9962
A11: 2.5 | B11: 3.0364
A12: 2.75 | B12: 3.0725
A13: 3 | B13: 3.1052
... A121: 30 | B121: 4.1655

Sheet Obligation
A1: Paramètres
A2: Coupon annuel (%) | B2: 4
A3: Échéance (années) | B3: 10
A4: Nominal | B4: 100
A5: Coupons par an | B5: 2
A7: t (années) | B7: Flux | C7: Taux zéro (%) | D7: Facteur EXP(-z*t) | E7: Flux actualisé | F7: t x flux actualisé
A8: =1/$B$5 | B8: =IF(ROUND(A8*$B$5,0)>ROUND($B$3*$B$5,0),0,$B$4*$B$2/100/$B$5+IF(ROUND(A8*$B$5,0)=ROUND($B$3*$B$5,0),$B$4,0)) | C8: =IFERROR(VLOOKUP(A8,Courbe!$A$2:$B$121,2,FALSE),0) | D8: =EXP(-C8/100*A8) | E8: =B8*D8 | F8: =A8*E8
A9: =2/$B$5 | B9: =IF(ROUND(A9*$B$5,0)>ROUND($B$3*$B$5,0),0,$B$4*$B$2/100/$B$5+IF(ROUND(A9*$B$5,0)=ROUND($B$3*$B$5,0),$B$4,0)) | C9: =IFERROR(VLOOKUP(A9,Courbe!$A$2:$B$121,2,FALSE),0) | D9: =EXP(-C9/100*A9) | E9: =B9*D9 | F9: =A9*E9
A10: =3/$B$5 | B10: =IF(ROUND(A10*$B$5,0)>ROUND($B$3*$B$5,0),0,$B$4*$B$2/100/$B$5+IF(ROUND(A10*$B$5,0)=ROUND($B$3*$B$5,0),$B$4,0)) | C10: =IFERROR(VLOOKUP(A10,Courbe!$A$2:$B$121,2,FALSE),0) | D10: =EXP(-C10/100*A10) | E10: =B10*D10 | F10: =A10*E10
A11: =4/$B$5 | B11: =IF(ROUND(A11*$B$5,0)>ROUND($B$3*$B$5,0),0,$B$4*$B$2/100/$B$5+IF(ROUND(A11*$B$5,0)=ROUND($B$3*$B$5,0),$B$4,0)) | C11: =IFERROR(VLOOKUP(A11,Courbe!$A$2:$B$121,2,FALSE),0) | D11: =EXP(-C11/100*A11) | E11: =B11*D11 | F11: =A11*E11
A12: =5/$B$5 | B12: =IF(ROUND(A12*$B$5,0)>ROUND($B$3*$B$5,0),0,$B$4*$B$2/100/$B$5+IF(ROUND(A12*$B$5,0)=ROUND($B$3*$B$5,0),$B$4,0)) | C12: =IFERROR(VLOOKUP(A12,Courbe!$A$2:$B$121,2,FALSE),0) | D12: =EXP(-C12/100*A12) | E12: =B12*D12 | F12: =A12*E12
A13: =6/$B$5 | B13: =IF(ROUND(A13*$B$5,0)>ROUND($B$3*$B$5,0),0,$B$4*$B$2/100/$B$5+IF(ROUND(A13*$B$5,0)=ROUND($B$3*$B$5,0),$B$4,0)) | C13: =IFERROR(VLOOKUP(A13,Courbe!$A$2:$B$121,2,FALSE),0) | D13: =EXP(-C13/100*A13) | E13: =B13*D13 | F13: =A13*E13
A14: =7/$B$5 | B14: =IF(ROUND(A14*$B$5,0)>ROUND($B$3*$B$5,0),0,$B$4*$B$2/100/$B$5+IF(ROUND(A14*$B$5,0)=ROUND($B$3*$B$5,0),$B$4,0)) | C14: =IFERROR(VLOOKUP(A14,Courbe!$A$2:$B$121,2,FALSE),0) | D14: =EXP(-C14/100*A14) | E14: =B14*D14 | F14: =A14*E14
A15: =8/$B$5 | B15: =IF(ROUND(A15*$B$5,0)>ROUND($B$3*$B$5,0),0,$B$4*$B$2/100/$B$5+IF(ROUND(A15*$B$5,0)=ROUND($B$3*$B$5,0),$B$4,0)) | C15: =IFERROR(VLOOKUP(A15,Courbe!$A$2:$B$121,2,FALSE),0) | D15: =EXP(-C15/100*A15) | E15: =B15*D15 | F15: =A15*E15
A16: =9/$B$5 | B16: =IF(ROUND(A16*$B$5,0)>ROUND($B$3*$B$5,0),0,$B$4*$B$2/100/$B$5+IF(ROUND(A16*$B$5,0)=ROUND($B$3*$B$5,0),$B$4,0)) | C16: =IFERROR(VLOOKUP(A16,Courbe!$A$2:$B$121,2,FALSE),0) | D16: =EXP(-C16/100*A16) | E16: =B16*D16 | F16: =A16*E16
A17: =10/$B$5 | B17: =IF(ROUND(A17*$B$5,0)>ROUND($B$3*$B$5,0),0,$B$4*$B$2/100/$B$5+IF(ROUND(A17*$B$5,0)=ROUND($B$3*$B$5,0),$B$4,0)) | C17: =IFERROR(VLOOKUP(A17,Courbe!$A$2:$B$121,2,FALSE),0) | D17: =EXP(-C17/100*A17) | E17: =B17*D17 | F17: =A17*E17
A18: =11/$B$5 | B18: =IF(ROUND(A18*$B$5,0)>ROUND($B$3*$B$5,0),0,$B$4*$B$2/100/$B$5+IF(ROUND(A18*$B$5,0)=ROUND($B$3*$B$5,0),$B$4,0)) | C18: =IFERROR(VLOOKUP(A18,Courbe!$A$2:$B$121,2,FALSE),0) | D18: =EXP(-C18/100*A18) | E18: =B18*D18 | F18: =A18*E18
A19: =12/$B$5 | B19: =IF(ROUND(A19*$B$5,0)>ROUND($B$3*$B$5,0),0,$B$4*$B$2/100/$B$5+IF(ROUND(A19*$B$5,0)=ROUND($B$3*$B$5,0),$B$4,0)) | C19: =IFERROR(VLOOKUP(A19,Courbe!$A$2:$B$121,2,FALSE),0) | D19: =EXP(-C19/100*A19) | E19: =B19*D19 | F19: =A19*E19
A20: =13/$B$5 | B20: =IF(ROUND(A20*$B$5,0)>ROUND($B$3*$B$5,0),0,$B$4*$B$2/100/$B$5+IF(ROUND(A20*$B$5,0)=ROUND($B$3*$B$5,0),$B$4,0)) | C20: =IFERROR(VLOOKUP(A20,Courbe!$A$2:$B$121,2,FALSE),0) | D20: =EXP(-C20/100*A20) | E20: =B20*D20 | F20: =A20*E20
A21: =14/$B$5 | B21: =IF(ROUND(A21*$B$5,0)>ROUND($B$3*$B$5,0),0,$B$4*$B$2/100/$B$5+IF(ROUND(A21*$B$5,0)=ROUND($B$3*$B$5,0),$B$4,0)) | C21: =IFERROR(VLOOKUP(A21,Courbe!$A$2:$B$121,2,FALSE),0) | D21: =EXP(-C21/100*A21) | E21: =B21*D21 | F21: =A21*E21
A22: =15/$B$5 | B22: =IF(ROUND(A22*$B$5,0)>ROUND($B$3*$B$5,0),0,$B$4*$B$2/100/$B$5+IF(ROUND(A22*$B$5,0)=ROUND($B$3*$B$5,0),$B$4,0)) | C22: =IFERROR(VLOOKUP(A22,Courbe!$A$2:$B$121,2,FALSE),0) | D22: =EXP(-C22/100*A22) | E22: =B22*D22 | F22: =A22*E22
A23: =16/$B$5 | B23: =IF(ROUND(A23*$B$5,0)>ROUND($B$3*$B$5,0),0,$B$4*$B$2/100/$B$5+IF(ROUND(A23*$B$5,0)=ROUND($B$3*$B$5,0),$B$4,0)) | C23: =IFERROR(VLOOKUP(A23,Courbe!$A$2:$B$121,2,FALSE),0) | D23: =EXP(-C23/100*A23) | E23: =B23*D23 | F23: =A23*E23
A24: =17/$B$5 | B24: =IF(ROUND(A24*$B$5,0)>ROUND($B$3*$B$5,0),0,$B$4*$B$2/100/$B$5+IF(ROUND(A24*$B$5,0)=ROUND($B$3*$B$5,0),$B$4,0)) | C24: =IFERROR(VLOOKUP(A24,Courbe!$A$2:$B$121,2,FALSE),0) | D24: =EXP(-C24/100*A24) | E24: =B24*D24 | F24: =A24*E24
A25: =18/$B$5 | B25: =IF(ROUND(A25*$B$5,0)>ROUND($B$3*$B$5,0),0,$B$4*$B$2/100/$B$5+IF(ROUND(A25*$B$5,0)=ROUND($B$3*$B$5,0),$B$4,0)) | C25: =IFERROR(VLOOKUP(A25,Courbe!$A$2:$B$121,2,FALSE),0) | D25: =EXP(-C25/100*A25) | E25: =B25*D25 | F25: =A25*E25
A26: =19/$B$5 | B26: =IF(ROUND(A26*$B$5,0)>ROUND($B$3*$B$5,0),0,$B$4*$B$2/100/$B$5+IF(ROUND(A26*$B$5,0)=ROUND($B$3*$B$5,0),$B$4,0)) | C26: =IFERROR(VLOOKUP(A26,Courbe!$A$2:$B$121,2,FALSE),0) | D26: =EXP(-C26/100*A26) | E26: =B26*D26 | F26: =A26*E26
A27: =20/$B$5 | B27: =IF(ROUND(A27*$B$5,0)>ROUND($B$3*$B$5,0),0,$B$4*$B$2/100/$B$5+IF(ROUND(A27*$B$5,0)=ROUND($B$3*$B$5,0),$B$4,0)) | C27: =IFERROR(VLOOKUP(A27,Courbe!$A$2:$B$121,2,FALSE),0) | D27: =EXP(-C27/100*A27) | E27: =B27*D27 | F27: =A27*E27
A28: =21/$B$5 | B28: =IF(ROUND(A28*$B$5,0)>ROUND($B$3*$B$5,0),0,$B$4*$B$2/100/$B$5+IF(ROUND(A28*$B$5,0)=ROUND($B$3*$B$5,0),$B$4,0)) | C28: =IFERROR(VLOOKUP(A28,Courbe!$A$2:$B$121,2,FALSE),0) | D28: =EXP(-C28/100*A28) | E28: =B28*D28 | F28: =A28*E28
A29: =22/$B$5 | B29: =IF(ROUND(A29*$B$5,0)>ROUND($B$3*$B$5,0),0,$B$4*$B$2/100/$B$5+IF(ROUND(A29*$B$5,0)=ROUND($B$3*$B$5,0),$B$4,0)) | C29: =IFERROR(VLOOKUP(A29,Courbe!$A$2:$B$121,2,FALSE),0) | D29: =EXP(-C29/100*A29) | E29: =B29*D29 | F29: =A29*E29
A30: =23/$B$5 | B30: =IF(ROUND(A30*$B$5,0)>ROUND($B$3*$B$5,0),0,$B$4*$B$2/100/$B$5+IF(ROUND(A30*$B$5,0)=ROUND($B$3*$B$5,0),$B$4,0)) | C30: =IFERROR(VLOOKUP(A30,Courbe!$A$2:$B$121,2,FALSE),0) | D30: =EXP(-C30/100*A30) | E30: =B30*D30 | F30: =A30*E30
A31: =24/$B$5 | B31: =IF(ROUND(A31*$B$5,0)>ROUND($B$3*$B$5,0),0,$B$4*$B$2/100/$B$5+IF(ROUND(A31*$B$5,0)=ROUND($B$3*$B$5,0),$B$4,0)) | C31: =IFERROR(VLOOKUP(A31,Courbe!$A$2:$B$121,2,FALSE),0) | D31: =EXP(-C31/100*A31) | E31: =B31*D31 | F31: =A31*E31
A32: =25/$B$5 | B32: =IF(ROUND(A32*$B$5,0)>ROUND($B$3*$B$5,0),0,$B$4*$B$2/100/$B$5+IF(ROUND(A32*$B$5,0)=ROUND($B$3*$B$5,0),$B$4,0)) | C32: =IFERROR(VLOOKUP(A32,Courbe!$A$2:$B$121,2,FALSE),0) | D32: =EXP(-C32/100*A32) | E32: =B32*D32 | F32: =A32*E32
A33: =26/$B$5 | B33: =IF(ROUND(A33*$B$5,0)>ROUND($B$3*$B$5,0),0,$B$4*$B$2/100/$B$5+IF(ROUND(A33*$B$5,0)=ROUND($B$3*$B$5,0),$B$4,0)) | C33: =IFERROR(VLOOKUP(A33,Courbe!$A$2:$B$121,2,FALSE),0) | D33: =EXP(-C33/100*A33) | E33: =B33*D33 | F33: =A33*E33
A34: =27/$B$5 | B34: =IF(ROUND(A34*$B$5,0)>ROUND($B$3*$B$5,0),0,$B$4*$B$2/100/$B$5+IF(ROUND(A34*$B$5,0)=ROUND($B$3*$B$5,0),$B$4,0)) | C34: =IFERROR(VLOOKUP(A34,Courbe!$A$2:$B$121,2,FALSE),0) | D34: =EXP(-C34/100*A34) | E34: =B34*D34 | F34: =A34*E34
A35: =28/$B$5 | B35: =IF(ROUND(A35*$B$5,0)>ROUND($B$3*$B$5,0),0,$B$4*$B$2/100/$B$5+IF(ROUND(A35*$B$5,0)=ROUND($B$3*$B$5,0),$B$4,0)) | C35: =IFERROR(VLOOKUP(A35,Courbe!$A$2:$B$121,2,FALSE),0) | D35: =EXP(-C35/100*A35) | E35: =B35*D35 | F35: =A35*E35
A36: =29/$B$5 | B36: =IF(ROUND(A36*$B$5,0)>ROUND($B$3*$B$5,0),0,$B$4*$B$2/100/$B$5+IF(ROUND(A36*$B$5,0)=ROUND($B$3*$B$5,0),$B$4,0)) | C36: =IFERROR(VLOOKUP(A36,Courbe!$A$2:$B$121,2,FALSE),0) | D36: =EXP(-C36/100*A36) | E36: =B36*D36 | F36: =A36*E36
A37: =30/$B$5 | B37: =IF(ROUND(A37*$B$5,0)>ROUND($B$3*$B$5,0),0,$B$4*$B$2/100/$B$5+IF(ROUND(A37*$B$5,0)=ROUND($B$3*$B$5,0),$B$4,0)) | C37: =IFERROR(VLOOKUP(A37,Courbe!$A$2:$B$121,2,FALSE),0) | D37: =EXP(-C37/100*A37) | E37: =B37*D37 | F37: =A37*E37
A38: =31/$B$5 | B38: =IF(ROUND(A38*$B$5,0)>ROUND($B$3*$B$5,0),0,$B$4*$B$2/100/$B$5+IF(ROUND(A38*$B$5,0)=ROUND($B$3*$B$5,0),$B$4,0)) | C38: =IFERROR(VLOOKUP(A38,Courbe!$A$2:$B$121,2,FALSE),0) | D38: =EXP(-C38/100*A38) | E38: =B38*D38 | F38: =A38*E38
A39: =32/$B$5 | B39: =IF(ROUND(A39*$B$5,0)>ROUND($B$3*$B$5,0),0,$B$4*$B$2/100/$B$5+IF(ROUND(A39*$B$5,0)=ROUND($B$3*$B$5,0),$B$4,0)) | C39: =IFERROR(VLOOKUP(A39,Courbe!$A$2:$B$121,2,FALSE),0) | D39: =EXP(-C39/100*A39) | E39: =B39*D39 | F39: =A39*E39
A40: =33/$B$5 | B40: =IF(ROUND(A40*$B$5,0)>ROUND($B$3*$B$5,0),0,$B$4*$B$2/100/$B$5+IF(ROUND(A40*$B$5,0)=ROUND($B$3*$B$5,0),$B$4,0)) | C40: =IFERROR(VLOOKUP(A40,Courbe!$A$2:$B$121,2,FALSE),0) | D40: =EXP(-C40/100*A40) | E40: =B40*D40 | F40: =A40*E40
A41: =34/$B$5 | B41: =IF(ROUND(A41*$B$5,0)>ROUND($B$3*$B$5,0),0,$B$4*$B$2/100/$B$5+IF(ROUND(A41*$B$5,0)=ROUND($B$3*$B$5,0),$B$4,0)) | C41: =IFERROR(VLOOKUP(A41,Courbe!$A$2:$B$121,2,FALSE),0) | D41: =EXP(-C41/100*A41) | E41: =B41*D41 | F41: =A41*E41
...

Sheet Chocs
A1: Échéance (années) | B1: Courbe de base (%) | C1: parallele_hausse | D1: parallele_baisse | E1: pentification | F1: aplatissement | G1: court_hausse | H1: court_baisse
A2: 0.25 | B2: =Courbe!B2 | C2: =$B2+2.0 | D2: =$B2+-2.0 | E2: =$B2+-1.5838 | F2: =$B2+2.0031 | G2: =$B2+2.5834 | H2: =$B2+-2.5834
A3: 0.5 | B3: =Courbe!B3 | C3: =$B3+2.0 | D3: =$B3+-2.0 | E3: =$B3+-1.3924 | F3: =$B3+1.8181 | G3: =$B3+2.4269 | H3: =$B3+-2.4269
A4: 0.75 | B4: =Courbe!B4 | C4: =$B4+2.0 | D4: =$B4+-2.0 | E4: =$B4+-1.2126 | F4: =$B4+1.6443 | G4: =$B4+2.2798 | H4: =$B4+-2.2798
A5: 1 | B5: =Courbe!B5 | C5: =$B5+2.0 | D5: =$B5+-2.0 | E5: =$B5+-1.0437 | F5: =$B5+1.4811 | G5: =$B5+2.1417 | H5: =$B5+-2.1417
A6: 1.25 | B6: =Courbe!B6 | C6: =$B6+2.0 | D6: =$B6+-2.0 | E6: =$B6+-0.8851 | F6: =$B6+1.3278 | G6: =$B6+2.0119 | H6: =$B6+-2.0119
A7: 1.5 | B7: =Courbe!B7 | C7: =$B7+2.0 | D7: =$B7+-2.0 | E7: =$B7+-0.736 | F7: =$B7+1.1837 | G7: =$B7+1.89 | H7: =$B7+-1.89
A8: 1.75 | B8: =Courbe!B8 | C8: =$B8+2.0 | D8: =$B8+-2.0 | E8: =$B8+-0.596 | F8: =$B8+1.0484 | G8: =$B8+1.7755 | H8: =$B8+-1.7755
A9: 2 | B9: =Courbe!B9 | C9: =$B9+2.0 | D9: =$B9+-2.0 | E9: =$B9+-0.4645 | F9: =$B9+0.9212 | G9: =$B9+1.668 | H9: =$B9+-1.668
A10: 2.25 | B10: =Courbe!B10 | C10: =$B10+2.0 | D10: =$B10+-2.0 | E10: =$B10+-0.3409 | F10: =$B10+0.8018 | G10: =$B10+1.5669 | H10: =$B10+-1.5669
A11: 2.5 | B11: =Courbe!B11 | C11: =$B11+2.0 | D11: =$B11+-2.0 | E11: =$B11+-0.2248 | F11: =$B11+0.6896 | G11: =$B11+1.472 | H11: =$B11+-1.472
A12: 2.75 | B12: =Courbe!B12 | C12: =$B12+2.0 | D12: =$B12+-2.0 | E12: =$B12+-0.1158 | F12: =$B12+0.5842 | G12: =$B12+1.3828 | H12: =$B12+-1.3828
A13: 3 | B13: =Courbe!B13 | C13: =$B13+2.0 | D13: =$B13+-2.0 | E13: =$B13+-0.0133 | F13: =$B13+0.4852 | G13: =$B13+1.299 | H13: =$B13+-1.299
A14: 3.25 | B14: =Courbe!B14 | C14: =$B14+2.0 | D14: =$B14+-2.0 | E14: =$B14+0.0829 | F14: =$B14+0.3922 | G14: =$B14+1.2203 | H14: =$B14+-1.2203
A15: 3.5 | B15: =Courbe!B15 | C15: =$B15+2.0 | D15: =$B15+-2.0 | E15: =$B15+0.1733 | F15: =$B15+0.3048 | G15: =$B15+1.1464 | H15: =$B15+-1.1464
A16: 3.75 | B16: =Courbe!B16 | C16: =$B16+2.0 | D16: =$B16+-2.0 | E16: =$B16+0.2582 | F16: =$B16+0.2227 | G16: =$B16+1.0769 | H16: =$B16+-1.0769
A17: 4 | B17: =Courbe!B17 | C17: =$B17+2.0 | D17: =$B17+-2.0 | E17: =$B17+0.338 | F17: =$B17+0.1456 | G17: =$B17+1.0117 | H17: =$B17+-1.0117
A18: 4.25 | B18: =Courbe!B18 | C18: =$B18+2.0 | D18: =$B18+-2.0 | E18: =$B18+0.413 | F18: =$B18+0.0732 | G18: =$B18+0.9504 | H18: =$B18+-0.9504
A19: 4.5 | B19: =Courbe!B19 | C19: =$B19+2.0 | D19: =$B19+-2.0 | E19: =$B19+0.4834 | F19: =$B19+0.0051 | G19: =$B19+0.8928 | H19: =$B19+-0.8928
A20: 4.75 | B20: =Courbe!B20 | C20: =$B20+2.0 | D20: =$B20+-2.0 | E20: =$B20+0.5495 | F20: =$B20+-0.0588 | G20: =$B20+0.8387 | H20: =$B20+-0.8387
A21: 5 | B21: =Courbe!B21 | C21: =$B21+2.0 | D21: =$B21+-2.0 | E21: =$B21+0.6116 | F21: =$B21+-0.1189 | G21: =$B21+0.7879 | H21: =$B21+-0.7879
A22: 5.25 | B22: =Courbe!B22 | C22: =$B22+2.0 | D22: =$B22+-2.0 | E22: =$B22+0.67 | F22: =$B22+-0.1753 | G22: =$B22+0.7402 | H22: =$B22+-0.7402
A23: 5.5 | B23: =Courbe!B23 | C23: =$B23+2.0 | D23: =$B23+-2.0 | E23: =$B23+0.7248 | F23: =$B23+-0.2283 | G23: =$B23+0.6953 | H23: =$B23+-0.6953
A24: 5.75 | B24: =Courbe!B24 | C24: =$B24+2.0 | D24: =$B24+-2.0 | E24: =$B24+0.7763 | F24: =$B24+-0.2781 | G24: =$B24+0.6532 | H24: =$B24+-0.6532
A25: 6 | B25: =Courbe!B25 | C25: =$B25+2.0 | D25: =$B25+-2.0 | E25: =$B25+0.8247 | F25: =$B25+-0.3248 | G25: =$B25+0.6136 | H25: =$B25+-0.6136
A26: 6.25 | B26: =Courbe!B26 | C26: =$B26+2.0 | D26: =$B26+-2.0 | E26: =$B26+0.8702 | F26: =$B26+-0.3688 | G26: =$B26+0.5764 | H26: =$B26+-0.5764
A27: 6.5 | B27: =Courbe!B27 | C27: =$B27+2.0 | D27: =$B27+-2.0 | E27: =$B27+0.9129 | F27: =$B27+-0.41 | G27: =$B27+0.5415 | H27: =$B27+-0.5415
A28: 6.75 | B28: =Courbe!B28 | C28: =$B28+2.0 | D28: =$B28+-2.0 | E28: =$B28+0.953 | F28: =$B28+-0.4488 | G28: =$B28+0.5087 | H28: =$B28+-0.5087
A29: 7 | B29: =Courbe!B29 | C29: =$B29+2.0 | D29: =$B29+-2.0 | E29: =$B29+0.9907 | F29: =$B29+-0.4852 | G29: =$B29+0.4779 | H29: =$B29+-0.4779
A30: 7.25 | B30: =Courbe!B30 | C30: =$B30+2.0 | D30: =$B30+-2.0 | E30: =$B30+1.0261 | F30: =$B30+-0.5195 | G30: =$B30+0.4489 | H30: =$B30+-0.4489
A31: 7.5 | B31: =Courbe!B31 | C31: =$B31+2.0 | D31: =$B31+-2.0 | E31: =$B31+1.0593 | F31: =$B31+-0.5516 | G31: =$B31+0.4217 | H31: =$B31+-0.4217
A32: 7.75 | B32: =Courbe!B32 | C32: =$B32+2.0 | D32: =$B32+-2.0 | E32: =$B32+1.0906 | F32: =$B32+-0.5818 | G32: =$B32+0.3962 | H32: =$B32+-0.3962
A33: 8 | B33: =Courbe!B33 | C33: =$B33+2.0 | D33: =$B33+-2.0 | E33: =$B33+1.1199 | F33: =$B33+-0.6102 | G33: =$B33+0.3722 | H33: =$B33+-0.3722
A34: 8.25 | B34: =Courbe!B34 | C34: =$B34+2.0 | D34: =$B34+-2.0 | E34: =$B34+1.1475 | F34: =$B34+-0.6368 | G34: =$B34+0.3496 | H34: =$B34+-0.3496
A35: 8.5 | B35: =Courbe!B35 | C35: =$B35+2.0 | D35: =$B35+-2.0 | E35: =$B35+1.1734 | F35: =$B35+-0.6618 | G35: =$B35+0.3284 | H35: =$B35+-0.3284
A36: 8.75 | B36: =Courbe!B36 | C36: =$B36+2.0 | D36: =$B36+-2.0 | E36: =$B36+1.1977 | F36: =$B36+-0.6854 | G36: =$B36+0.3085 | H36: =$B36+-0.3085
A37: 9 | B37: =Courbe!B37 | C37: =$B37+2.0 | D37: =$B37+-2.0 | E37: =$B37+1.2206 | F37: =$B37+-0.7075 | G37: =$B37+0.2898 | H37: =$B37+-0.2898
A38: 9.25 | B38: =Courbe!B38 | C38: =$B38+2.0 | D38: =$B38+-2.0 | E38: =$B38+1.2421 | F38: =$B38+-0.7282 | G38: =$B38+0.2723 | H38: =$B38+-0.2723
A39: 9.5 | B39: =Courbe!B39 | C39: =$B39+2.0 | D39: =$B39+-2.0 | E39: =$B39+1.2622 | F39: =$B39+-0.7477 | G39: =$B39+0.2558 | H39: =$B39+-0.2558
A40: 9.75 | B40: =Courbe!B40 | C40: =$B40+2.0 | D40: =$B40+-2.0 | E40: =$B40+1.2812 | F40: =$B40+-0.766 | G40: =$B40+0.2403 | H40: =$B40+-0.2403
...
